Summary:
Procedure#waitForLatch may not throw error even there is one
Description:
On Suse, TestProcedureCoordinator#testUnreachableControllerDuringCommit often fails with stack trace pasted at the bottom.
The failure is due to a race condition that if current procedure throws error in the last wait because we don't check error after while wait loop.
When I looked at the failure, I found the related code in file ForeignExceptionDispatcher#receive may have an issue. Though we create a new exception, we still pass e to dispatch when e is null. Jonathan Hsieh Do you know if it's by design?
    if (e != null) {
      exception = e;
    } else {
      exception = new ForeignException(name, "");
    }

    // notify all the listeners
    dispatch(e);
Test case failure stack trace:

java.io.IOException via some op:java.io.IOException: Failed to reach controller during prepare
 at org.apache.hadoop.hbase.errorhandling.ForeignExceptionDispatcher.rethrowException(ForeignExceptionDispatcher.java:85)
 at org.apache.hadoop.hbase.procedure.Procedure.waitForLatch(Procedure.java:371)
 at org.apache.hadoop.hbase.procedure.Procedure.waitForCompleted(Procedure.java:343)
 at org.apache.hadoop.hbase.procedure.TestProcedureCoordinator.testUnreachableControllerDuringCommit(TestProcedureCoordinator.java:171)
 at sun.reflect.NativeMethodAccessorImpl.invoke0(Native Method)
 at sun.reflect.NativeMethodAccessorImpl.invoke(NativeMethodAccessorImpl.java:39)
 at sun.reflect.DelegatingMethodAccessorImpl.invoke(DelegatingMethodAccessorImpl.java:25)
 at java.lang.reflect.Method.invoke(Method.java:597)
 at org.junit.runners.model.FrameworkMethod$1.runReflectiveCall(FrameworkMethod.java:47)
 at org.junit.internal.runners.model.ReflectiveCallable.run(ReflectiveCallable.java:12)
 at org.junit.runners.model.FrameworkMethod.invokeExplosively(FrameworkMethod.java:44)
 at org.junit.internal.runners.statements.InvokeMethod.evaluate(InvokeMethod.java:17)
 at org.junit.internal.runners.statements.FailOnTimeout$StatementThread.run(FailOnTimeout.java:74)
Caused by: java.io.IOException: Failed to reach controller during prepare
 at org.apache.hadoop.hbase.procedure.Procedure.call(Procedure.java:212)
 at org.apache.hadoop.hbase.procedure.Procedure.call(Procedure.java:68)
 at java.util.concurrent.FutureTask$Sync.innerRun(FutureTask.java:303)
 at java.util.concurrent.FutureTask.run(FutureTask.java:138)
 at java.util.concurrent.ThreadPoolExecutor$Worker.runTask(ThreadPoolExecutor.java:886)
 at java.util.concurrent.ThreadPoolExecutor$Worker.run(ThreadPoolExecutor.java:908)
 at java.lang.Thread.run(Thread.java:662)
Status:
CLOSED
Priority:
Major
Resolution:
Fixed
Affects_version:
None
Fix_version:
0.98.0, 0.96.0
Component:
None
Label:
None
Environment:

Attachment number:
0
Assignee:
Jeffrey Zhong
Reporter:
Jeffrey Zhong
Create date:
23/Aug/13 05:08
Update date:
20/Nov/15 11:52
Resolved date:
24/Aug/13 01:13
